<mujoco model="URDFV2_cylinder_collision">
  <compiler angle="radian" meshdir="assets"/>

  <asset>
    <texture type="skybox" builtin="gradient" rgb1="0.4 0.6 0.8" rgb2="0 0 0" width="512" height="512"/>
    <texture name="texplane" type="2d" builtin="checker" rgb1=".2 .3 .4" rgb2=".1 .15 .2" width="512" height="512" mark="cross" markrgb=".8 .8 .8"/>
    <material name="matplane" reflectance="0.3" texture="texplane" texrepeat="1 1" texuniform="true"/>

    <mesh name="BaseLink" file="BaseLink.STL"/>
    <mesh name="LFootLink" file="LFootLink.STL"/>
    <mesh name="LHipLink" file="LHipLink.STL"/>
    <mesh name="LLowerLink1" file="LLowerLink1.STL"/>
    <mesh name="LLowerLink2" file="LLowerLink2.STL"/>
    <mesh name="LShankLink" file="LShankLink.STL"/>
    <mesh name="LShankSpringLink" file="LShankSpringLink.STL"/>
    <mesh name="LShankSpringLinkL" file="LShankSpringLinkL.STL"/>
    <mesh name="LSpringLink" file="LSpringLink.STL"/>
    <mesh name="LSpringLinkL" file="LSpringLinkL.STL"/>
    <mesh name="LUpperLink" file="LUpperLink.STL"/>
    <mesh name="RFootLink" file="RFootLink.STL"/>
    <mesh name="RHipLink" file="RHipLink.STL"/>
    <mesh name="RLowerLink1" file="RLowerLink1.STL"/>
    <mesh name="RLowerLink2" file="RLowerLink2.STL"/>
    <mesh name="RShankLink" file="RShankLink.STL"/>
    <mesh name="RShankSpringLink" file="RShankSpringLink.STL"/>
    <mesh name="RShankSpringLinkL" file="RShankSpringLinkL.STL"/>
    <mesh name="RSpringLink" file="RSpringLink.STL"/>
    <mesh name="RSpringLinkL" file="RSpringLinkL.STL"/>
    <mesh name="RUpperLink" file="RUpperLink.STL"/>
  </asset>

  <worldbody>
    <light directional="true" diffuse=".8 .8 .8" specular=".2 .2 .2" pos="0 0 5" dir="0 0 -1"/>
    <light directional="false" diffuse=".5 .5 .5" specular="0 0 0" pos="0 0 2" dir="0 0 -1" mode="trackcom"/>
    <geom name="floor" type="plane" size="5 5 0.1" pos="0 0 0" material="matplane" condim="3"/>

    <body name="BaseLink" pos="0 0 0.7">
      <inertial pos="0.000028 0.00303 -0.13936" mass="1.756" diaginertia="0.0120985 0.0166907 0.0106056"/>
      <!-- visual -->
      <geom pos="0 0 0" contype="0" conaffinity="0" group="1" density="0" rgba="0.5569 0.5569 0.5569 1" type="mesh" mesh="BaseLink"/>
      <!-- collision: box -->
      <geom pos="0 0 -0.1" contype="1" conaffinity="1" group="3" density="0" rgba="0.3 0.3 0.3 0.3" type="box" size="0.1 0.11 0.1"/>
      <freejoint name="floating_base_joint"/>
      <site name="imu" pos="0 0 -0.05"/>

      <!-- ====== LEFT LEG ====== -->
      <body name="LHipLink" pos="0.075 -0.029215 -0.189354" quat="0 0 -0.7071068 0.7071068">
        <inertial pos="0.001718 -0.000048 0.03364" mass="0.457" diaginertia="0.000251 0.0002795 0.0002244"/>
        <joint name="LHipJoint" pos="0 0 0" type="hinge" axis="0 0 -1" range="-0.7854 0.7854" actuatorfrcrange="-27 27"/>
        <geom pos="0 0 0" contype="0" conaffinity="0" group="1" density="0" rgba="0.898 0.9176 0.9255 1" type="mesh" mesh="LHipLink"/>
        <geom pos="0.0017 0 0.0336" contype="1" conaffinity="1" group="3" density="0" rgba="0.3 0.3 0.3 0.3" type="cylinder" size="0.03 0.05"/>

        <body name="LUpperLink" pos="-0.031125 0 0.038" quat="0.4999982 0.5 0.5000018 0.5">
          <inertial pos="0.15453 0.001338 0.032893" mass="0.588" diaginertia="0.0003673 0.0026925 0.0025714"/>
          <joint name="LUpperJoint" pos="0 0 0" type="hinge" axis="0 0 -1" range="-0.7854 1.0472" actuatorfrcrange="-27 27"/>
          <geom pos="0 0 0" contype="0" conaffinity="0" group="1" density="0" rgba="0.898 0.9176 0.9255 1" type="mesh" mesh="LUpperLink"/>
          <geom pos="0.1545 0.0013 0.0329" euler="0 1.5708 0" contype="1" conaffinity="1" group="3" density="0" rgba="0.3 0.3 0.3 0.3" type="cylinder" size="0.035 0.11"/>

          <body name="LLowerLink1" pos="0.19222 0 -0.0067634" quat="-0.0000037 0 0 1">
            <inertial pos="-0.003811 0.074686 0.03886" mass="0.168" diaginertia="0.0007929 0.0001215 0.0007175"/>
            <joint name="LLowerJoint1" pos="0 0 0" type="hinge" axis="0 0 -1" range="-3.14159 3.14159" actuatorfrcrange="-27 27"/>
            <geom pos="0 0 0" contype="0" conaffinity="0" group="1" density="0" rgba="0.898 0.9176 0.9255 1" type="mesh" mesh="LLowerLink1"/>
            <geom pos="-0.0038 0.0747 0.0389" euler="1.5708 0 0" contype="1" conaffinity="1" group="3" density="0" rgba="0.3 0.3 0.3 0.3" type="cylinder" size="0.02 0.095"/>

            <body name="LShankLink" pos="0.0000544 0.20893 0.026963" quat="0 -0.0000037 1 -0.0000037">
              <inertial pos="0.036204 0.005206 -0.011037" mass="0.118" diaginertia="0.0000182 0.0004906 0.0004904"/>
              <joint name="LShankJoint" pos="0 0 0" type="hinge" axis="0 0 -1" range="-3.14159 3.14159" actuatorfrcrange="-27 27"/>
              <geom pos="0 0 0" contype="0" conaffinity="0" group="1" density="0" rgba="0.898 0.9176 0.9255 1" type="mesh" mesh="LShankLink"/>
              <geom pos="0.0362 0.0052 -0.011" euler="0 1.5708 0" contype="1" conaffinity="1" group="3" density="0" rgba="0.3 0.3 0.3 0.3" type="cylinder" size="0.018 0.108"/>

              <body name="LFootLink" pos="0.14463 0.0058657 0.007" quat="0 -0.0000037 1 -0.0000037">
                <inertial pos="-0.01521 -0.021335 0.019469" mass="0.088" diaginertia="0.0000647 0.0000257 0.0000616"/>
                <joint name="LFootJoint" pos="0 0 0" type="hinge" axis="0 0 -1" range="-1.0472 1.0472" actuatorfrcrange="-27 27"/>
                <!-- visual + collision: keep mesh -->
                <geom name="LFootLink" pos="0 0 0" contype="1" conaffinity="1" group="1" density="0" rgba="0.898 0.9176 0.9255 1" type="mesh" mesh="LFootLink"/>
                <site name="left_foot" pos="0 0 0.04" size="0.01"/>
              </body>

              <body name="LShankSpringLink" pos="0.030199 -0.0042978 -0.0092865" quat="0.7043833 0.0619865 0.7043859 -0.0619867">
                <inertial pos="0.00175 0 0.042154" mass="0.022" diaginertia="0.0000155 0.0000155 0.0000004"/>
                <joint name="LShankSpringJoint" pos="0 0 0" type="hinge" axis="-1 0 0" range="-3.14159 3.14159" actuatorfrcrange="-27 27"/>
                <geom pos="0 0 0" contype="0" conaffinity="0" group="1" density="0" rgba="0.898 0.9176 0.9255 1" type="mesh" mesh="LShankSpringLink"/>

                <body name="LShankSpringLinkL">
                  <inertial pos="0.00175 0 0.093678" mass="0.017" diaginertia="0.0000077 0.0000077 0.0000001"/>
                  <joint name="LShankSpringJointL" pos="0 0 0" type="slide" axis="0 0 1" range="-0.2 0.2" stiffness="200" damping="2" springref="0" actuatorfrcrange="-50 50"/>
                  <geom pos="0 0 0" contype="0" conaffinity="0" group="1" density="0" rgba="0.6471 0.6196 0.5882 1" type="mesh" mesh="LShankSpringLinkL"/>
                </body>
              </body>
            </body>
          </body>

          <body name="LLowerLink2" pos="0.12 0 0.0052366" quat="0 1 0 0">
            <inertial pos="-0.006875 0.1029 -0.026" mass="0.138" diaginertia="0.0005849 0.0000433 0.000572"/>
            <joint name="LLowerJoint2" pos="0 0 0" type="hinge" axis="0 0 -1" range="-3.14159 3.14159" actuatorfrcrange="-27 27"/>
            <geom pos="0 0 0" contype="0" conaffinity="0" group="1" density="0" rgba="0.898 0.9176 0.9255 1" type="mesh" mesh="LLowerLink2"/>
            <geom pos="-0.0069 0.1029 -0.026" euler="1.5708 0 0" contype="1" conaffinity="1" group="3" density="0" rgba="0.3 0.3 0.3 0.3" type="cylinder" size="0.02 0.11"/>
          </body>

          <body name="LSpringLink" pos="0.12 0 0.0052366" quat="0 1 0 0">
            <inertial pos="0.02333 0.067547 -0.026" mass="0.174" diaginertia="0.0002101 0.0000328 0.0002342"/>
            <joint name="LSpringJoint" pos="0 0 0" type="hinge" axis="0 0 -1" range="-3.14159 3.14159" actuatorfrcrange="-27 27"/>
            <geom pos="0 0 0" contype="0" conaffinity="0" group="1" density="0" rgba="0.6471 0.6157 0.5843 1" type="mesh" mesh="LSpringLink"/>

            <body name="LSpringLinkL">
              <inertial pos="0.049906 0.144491 -0.026" mass="0.077" diaginertia="0.0000925 0.0000119 0.0001034"/>
              <joint name="LSpringJointL" pos="0 0 0" type="slide" axis="-0.32646 -0.94521 0" range="-0.2 0.2" stiffness="500" damping="2" springref="-0.04" actuatorfrcrange="-50 50"/>
              <geom pos="0 0 0" contype="0" conaffinity="0" group="1" density="0" rgba="0.6471 0.6157 0.5843 1" type="mesh" mesh="LSpringLinkL"/>
            </body>
          </body>
        </body>
      </body>

      <!-- ====== RIGHT LEG (mirror) ====== -->
      <body name="RHipLink" pos="-0.075 -0.029215 -0.189354" quat="0 0 0.7071068 -0.7071068">
        <inertial pos="0.001718 0.000066 0.033566" mass="0.457" diaginertia="0.0002507 0.0002786 0.000225"/>
        <joint name="RHipJoint" pos="0 0 0" type="hinge" axis="0 0 -1" range="-0.7854 0.7854" actuatorfrcrange="-27 27"/>
        <geom pos="0 0 0" contype="0" conaffinity="0" group="1" density="0" rgba="1 1 1 1" type="mesh" mesh="RHipLink"/>
        <geom pos="0.0017 0.0001 0.0336" contype="1" conaffinity="1" group="3" density="0" rgba="0.3 0.3 0.3 0.3" type="cylinder" size="0.03 0.05"/>

        <body name="RUpperLink" pos="0.031125 0 0.038" quat="0.5 -0.5 -0.5 0.5">
          <inertial pos="0.154527 -0.001328 0.029357" mass="0.588" diaginertia="0.0003674 0.0026923 0.0025713"/>
          <joint name="RUpperJoint" pos="0 0 0" type="hinge" axis="0 0 -1" range="-0.7854 1.0472" actuatorfrcrange="-27 27"/>
          <geom pos="0 0 0" contype="0" conaffinity="0" group="1" density="0" rgba="0.898 0.9176 0.9255 1" type="mesh" mesh="RUpperLink"/>
          <geom pos="0.1545 -0.0013 0.0294" euler="0 1.5708 0" contype="1" conaffinity="1" group="3" density="0" rgba="0.3 0.3 0.3 0.3" type="cylinder" size="0.035 0.11"/>

          <body name="RLowerLink1" pos="0.1922151 0 -0.0073642" quat="0 0 1 0">
            <inertial pos="-0.003811 0.074686 -0.037517" mass="0.168" diaginertia="0.0007929 0.0001215 0.0007175"/>
            <joint name="RLowerJoint1" pos="0 0 0" type="hinge" axis="0 0 -1" range="-3.14159 3.14159" actuatorfrcrange="-27 27"/>
            <geom pos="0 0 0" contype="0" conaffinity="0" group="1" density="0" rgba="0.898 0.9176 0.9255 1" type="mesh" mesh="RLowerLink1"/>
            <geom pos="-0.0038 0.0747 -0.0375" euler="1.5708 0 0" contype="1" conaffinity="1" group="3" density="0" rgba="0.3 0.3 0.3 0.3" type="cylinder" size="0.02 0.095"/>

            <body name="RShankLink" pos="0.0000544 0.2089259 -0.0271523" quat="0 0 1 0">
              <inertial pos="0.036204 0.005206 0.011037" mass="0.118" diaginertia="0.0000182 0.0004906 0.0004904"/>
              <joint name="RShankJoint" pos="0 0 0" type="hinge" axis="0 0 -1" range="-3.14159 3.14159" actuatorfrcrange="-27 27"/>
              <geom pos="0 0 0" contype="0" conaffinity="0" group="1" density="0" rgba="0.898 0.9176 0.9255 1" type="mesh" mesh="RShankLink"/>
              <geom pos="0.0362 0.0052 0.011" euler="0 1.5708 0" contype="1" conaffinity="1" group="3" density="0" rgba="0.3 0.3 0.3 0.3" type="cylinder" size="0.018 0.108"/>

              <body name="RFootLink" pos="0.1446251 0.0058647 -0.007" quat="0 0 1 0">
                <inertial pos="-0.01521 -0.021335 -0.016604" mass="0.088" diaginertia="0.0000647 0.0000257 0.0000616"/>
                <joint name="RFootJoint" pos="0 0 0" type="hinge" axis="0 0 -1" range="-1.0472 1.0472" actuatorfrcrange="-27 27"/>
                <!-- visual + collision: keep mesh -->
                <geom name="RFootLink" pos="0 0 0" contype="1" conaffinity="1" group="1" density="0" rgba="0.898 0.9176 0.9255 1" type="mesh" mesh="RFootLink"/>
                <site name="right_foot" pos="0 0 -0.04" size="0.01"/>
              </body>

              <body name="RShankSpringLink" pos="0.030199 -0.004298 0.0092865" quat="0.704383 0.06199 0.7043856 -0.0619903">
                <inertial pos="-0.00175 0 0.042154" mass="0.022" diaginertia="0.0000155 0.0000155 0.0000004"/>
                <joint name="RShankSpringJoint" pos="0 0 0" type="hinge" axis="-1 0 0" range="-3.14159 3.14159" actuatorfrcrange="-27 27"/>
                <geom pos="0 0 0" contype="0" conaffinity="0" group="1" density="0" rgba="0.898 0.9176 0.9255 1" type="mesh" mesh="RShankSpringLink"/>

                <body name="RShankSpringLinkL">
                  <inertial pos="-0.00175 0 0.093678" mass="0.017" diaginertia="0.0000077 0.0000077 0.0000001"/>
                  <joint name="RShankSpringJointL" pos="0 0 0" type="slide" axis="0 0 1" range="-0.2 0.2" stiffness="200" damping="2" springref="0" actuatorfrcrange="-50 50"/>
                  <geom pos="0 0 0" contype="0" conaffinity="0" group="1" density="0" rgba="0.6471 0.6157 0.5843 1" type="mesh" mesh="RShankSpringLinkL"/>
                </body>
              </body>
            </body>
          </body>

          <body name="RLowerLink2" pos="0.12 0 0.012788" quat="0 -0.0000037 -1 0.0000037">
            <inertial pos="0.006875 0.1031 -0.018037" mass="0.138" diaginertia="0.0005849 0.0000433 0.000572"/>
            <joint name="RLowerJoint2" pos="0 0 0" type="hinge" axis="0 0 -1" range="-3.14159 3.14159" actuatorfrcrange="-27 27"/>
            <geom pos="0 0 0" contype="0" conaffinity="0" group="1" density="0" rgba="0.898 0.9176 0.9255 1" type="mesh" mesh="RLowerLink2"/>
            <geom pos="0.0069 0.1031 -0.018" euler="1.5708 0 0" contype="1" conaffinity="1" group="3" density="0" rgba="0.3 0.3 0.3 0.3" type="cylinder" size="0.02 0.11"/>
          </body>

          <body name="RSpringLink" pos="0.12 0 0.0127881" quat="0 0 -1 0">
            <inertial pos="-0.02333 0.067547 -0.018225" mass="0.174" diaginertia="0.0002101 0.0000328 0.0002342"/>
            <joint name="RSpringJoint" pos="0 0 0" type="hinge" axis="0 0 -1" range="-3.14159 3.14159" actuatorfrcrange="-27 27"/>
            <geom pos="0 0 0" contype="0" conaffinity="0" group="1" density="0" rgba="0.6471 0.6157 0.5843 1" type="mesh" mesh="RSpringLink"/>

            <body name="RSpringLinkL">
              <inertial pos="-0.049906 0.144491 -0.018225" mass="0.077" diaginertia="0.0000925 0.0000119 0.0001034"/>
              <joint name="RSpringJointL" pos="0 0 0" type="slide" axis="0.32646 -0.94521 0" range="-0.2 0.2" stiffness="500" damping="5" springref="-0.04" actuatorfrcrange="-50 50"/>
              <geom pos="0 0 0" contype="0" conaffinity="0" group="1" density="0" rgba="0.6471 0.6157 0.5843 1" type="mesh" mesh="RSpringLinkL"/>
            </body>
          </body>
        </body>
      </body>
    </body>
  </worldbody>

  <equality>
    <connect name="L_Lower_Loop" body1="LLowerLink2" body2="LShankLink" anchor="0 0.206 -0.00796" solref="0.005 1"/>
    <connect name="L_Spring_Loop" body1="LSpringLinkL" body2="LShankLink" anchor="0.07216 0.20893 0" solref="0.005 1"/>
    <connect name="L_Foot_Spring_Loop" body1="LShankSpringLinkL" body2="LFootLink" anchor="0 0 0.12742" solref="0.005 1"/>

    <connect name="R_Lower_Loop" body1="RLowerLink2" body2="RShankLink" anchor="0 0.206 0" solref="0.005 1"/>
    <connect name="R_Spring_Loop" body1="RSpringLinkL" body2="RShankLink" anchor="-0.07216 0.20893 0" solref="0.005 1"/>
    <connect name="R_Foot_Spring_Loop" body1="RShankSpringLinkL" body2="RFootLink" anchor="0 0 0.12742" solref="0.005 1"/>
  </equality>

  <contact>
    <!-- ===== Left Leg: serial chain ===== -->
    <exclude body1="BaseLink"   body2="LHipLink"/>
    <exclude body1="BaseLink"   body2="LUpperLink"/>
    <exclude body1="LHipLink"   body2="LUpperLink"/>
    <exclude body1="LUpperLink" body2="LLowerLink1"/>
    <exclude body1="LLowerLink1" body2="LShankLink"/>
    <exclude body1="LShankLink" body2="LFootLink"/>
    <exclude body1="LShankLink" body2="LShankSpringLink"/>
    <exclude body1="LShankSpringLink" body2="LShankSpringLinkL"/>
    <exclude body1="LUpperLink" body2="LLowerLink2"/>
    <exclude body1="LUpperLink" body2="LSpringLink"/>
    <exclude body1="LSpringLink" body2="LSpringLinkL"/>
    <!-- ===== Left Leg: parallel loops ===== -->
    <exclude body1="LLowerLink2" body2="LShankLink"/>
    <exclude body1="LSpringLinkL" body2="LShankLink"/>
    <exclude body1="LShankSpringLinkL" body2="LFootLink"/>
    <exclude body1="LSpringLink" body2="LLowerLink2"/>
    <exclude body1="LLowerLink1" body2="LSpringLinkL"/>
    <exclude body1="LLowerLink1" body2="LSpringLink"/>
    <exclude body1="LShankLink" body2="LShankSpringLinkL"/>
    <!-- ===== Right Leg: serial chain ===== -->
    <exclude body1="BaseLink"   body2="RHipLink"/>
    <exclude body1="BaseLink"   body2="RUpperLink"/>
    <exclude body1="RHipLink"   body2="RUpperLink"/>
    <exclude body1="RUpperLink" body2="RLowerLink1"/>
    <exclude body1="RLowerLink1" body2="RShankLink"/>
    <exclude body1="RShankLink" body2="RFootLink"/>
    <exclude body1="RShankLink" body2="RShankSpringLink"/>
    <exclude body1="RShankSpringLink" body2="RShankSpringLinkL"/>
    <exclude body1="RUpperLink" body2="RLowerLink2"/>
    <exclude body1="RUpperLink" body2="RSpringLink"/>
    <exclude body1="RSpringLink" body2="RSpringLinkL"/>
    <!-- ===== Right Leg: parallel loops ===== -->
    <exclude body1="RLowerLink2" body2="RShankLink"/>
    <exclude body1="RSpringLinkL" body2="RShankLink"/>
    <exclude body1="RShankSpringLinkL" body2="RFootLink"/>
    <exclude body1="RSpringLink" body2="RLowerLink2"/>
    <exclude body1="RLowerLink1" body2="RSpringLinkL"/>
    <exclude body1="RLowerLink1" body2="RSpringLink"/>
    <exclude body1="RShankLink" body2="RShankSpringLinkL"/>
  </contact>

  <sensor>
    <gyro name="imu_ang_vel" site="imu"/>
    <velocimeter name="imu_lin_vel" site="imu"/>
    <accelerometer name="imu_lin_acc" site="imu"/>
    <subtreeangmom name="root_angmom" body="BaseLink"/>
  </sensor>
</mujoco>
